[2024-04-02T21:26:19.170+0000] {taskinstance.py:1979} INFO - Dependencies all met for dep_context=non-requeueable deps ti=<TaskInstance: data_ingestion_dag.ingest_data_to_postgres manual__2024-04-02T21:21:03.211668+00:00 [queued]>
[2024-04-02T21:26:19.182+0000] {taskinstance.py:1979} INFO - Dependencies all met for dep_context=requeueable deps ti=<TaskInstance: data_ingestion_dag.ingest_data_to_postgres manual__2024-04-02T21:21:03.211668+00:00 [queued]>
[2024-04-02T21:26:19.183+0000] {taskinstance.py:2193} INFO - Starting attempt 2 of 2
[2024-04-02T21:26:19.203+0000] {taskinstance.py:2217} INFO - Executing <Task(PythonOperator): ingest_data_to_postgres> on 2024-04-02 21:21:03.211668+00:00
[2024-04-02T21:26:19.211+0000] {standard_task_runner.py:60} INFO - Started process 160 to run task
[2024-04-02T21:26:19.215+0000] {standard_task_runner.py:87} INFO - Running: ['***', 'tasks', 'run', 'data_ingestion_dag', 'ingest_data_to_postgres', 'manual__2024-04-02T21:21:03.211668+00:00', '--job-id', '48', '--raw', '--subdir', 'DAGS_FOLDER/***_dags.py', '--cfg-path', '/tmp/tmpmq0b3kb3']
[2024-04-02T21:26:19.218+0000] {standard_task_runner.py:88} INFO - Job 48: Subtask ingest_data_to_postgres
[2024-04-02T21:26:19.291+0000] {task_command.py:423} INFO - Running <TaskInstance: data_ingestion_dag.ingest_data_to_postgres manual__2024-04-02T21:21:03.211668+00:00 [running]> on host 7a8b7eb1ccbc
[2024-04-02T21:26:19.405+0000] {taskinstance.py:2513} INFO - Exporting env vars: AIRFLOW_CTX_DAG_OWNER='***' AIRFLOW_CTX_DAG_ID='data_ingestion_dag' AIRFLOW_CTX_TASK_ID='ingest_data_to_postgres' AIRFLOW_CTX_EXECUTION_DATE='2024-04-02T21:21:03.211668+00:00' AIRFLOW_CTX_TRY_NUMBER='2' AIRFLOW_CTX_DAG_RUN_ID='manual__2024-04-02T21:21:03.211668+00:00'
[2024-04-02T21:26:19.421+0000] {base.py:83} INFO - Using connection ID 'postgres_default' for task execution.
[2024-04-02T21:26:19.427+0000] {taskinstance.py:2731} ERROR - Task failed with exception
Traceback (most recent call last):
  File "/home/airflow/.local/lib/python3.8/site-packages/airflow/models/taskinstance.py", line 444, in _execute_task
    result = _execute_callable(context=context, **execute_callable_kwargs)
  File "/home/airflow/.local/lib/python3.8/site-packages/airflow/models/taskinstance.py", line 414, in _execute_callable
    return execute_callable(context=context, **execute_callable_kwargs)
  File "/home/airflow/.local/lib/python3.8/site-packages/airflow/operators/python.py", line 200, in execute
    return_value = self.execute_callable()
  File "/home/airflow/.local/lib/python3.8/site-packages/airflow/operators/python.py", line 217, in execute_callable
    return self.python_callable(*self.op_args, **self.op_kwargs)
  File "/opt/airflow/dags/airflow_dags.py", line 27, in ingest_data_to_postgres
    row['Name'], row['Address'], row['Transaction Amount'], row['Transaction Date'],
KeyError: 'Name'
[2024-04-02T21:26:19.440+0000] {taskinstance.py:1149} INFO - Marking task as FAILED. dag_id=data_ingestion_dag, task_id=ingest_data_to_postgres, execution_date=20240402T212103, start_date=20240402T212619, end_date=20240402T212619
[2024-04-02T21:26:19.459+0000] {standard_task_runner.py:107} ERROR - Failed to execute job 48 for task ingest_data_to_postgres ('Name'; 160)
[2024-04-02T21:26:19.526+0000] {local_task_job_runner.py:234} INFO - Task exited with return code 1
[2024-04-02T21:26:19.557+0000] {taskinstance.py:3312} INFO - 0 downstream tasks scheduled from follow-on schedule check
