[2024-04-02T08:26:58.543+0000] {taskinstance.py:1979} INFO - Dependencies all met for dep_context=non-requeueable deps ti=<TaskInstance: data_ingestion_dag.ingest_data_to_postgres manual__2024-04-02T08:21:49.372629+00:00 [queued]>
[2024-04-02T08:26:58.560+0000] {taskinstance.py:1979} INFO - Dependencies all met for dep_context=requeueable deps ti=<TaskInstance: data_ingestion_dag.ingest_data_to_postgres manual__2024-04-02T08:21:49.372629+00:00 [queued]>
[2024-04-02T08:26:58.562+0000] {taskinstance.py:2193} INFO - Starting attempt 2 of 2
[2024-04-02T08:26:58.586+0000] {taskinstance.py:2217} INFO - Executing <Task(PythonOperator): ingest_data_to_postgres> on 2024-04-02 08:21:49.372629+00:00
[2024-04-02T08:26:58.595+0000] {standard_task_runner.py:60} INFO - Started process 201 to run task
[2024-04-02T08:26:58.599+0000] {standard_task_runner.py:87} INFO - Running: ['***', 'tasks', 'run', 'data_ingestion_dag', 'ingest_data_to_postgres', 'manual__2024-04-02T08:21:49.372629+00:00', '--job-id', '44', '--raw', '--subdir', 'DAGS_FOLDER/***_dags.py', '--cfg-path', '/tmp/tmpr_cm41go']
[2024-04-02T08:26:58.603+0000] {standard_task_runner.py:88} INFO - Job 44: Subtask ingest_data_to_postgres
[2024-04-02T08:26:58.683+0000] {task_command.py:423} INFO - Running <TaskInstance: data_ingestion_dag.ingest_data_to_postgres manual__2024-04-02T08:21:49.372629+00:00 [running]> on host 48391dec7415
[2024-04-02T08:26:58.798+0000] {taskinstance.py:2513} INFO - Exporting env vars: AIRFLOW_CTX_DAG_OWNER='***' AIRFLOW_CTX_DAG_ID='data_ingestion_dag' AIRFLOW_CTX_TASK_ID='ingest_data_to_postgres' AIRFLOW_CTX_EXECUTION_DATE='2024-04-02T08:21:49.372629+00:00' AIRFLOW_CTX_TRY_NUMBER='2' AIRFLOW_CTX_DAG_RUN_ID='manual__2024-04-02T08:21:49.372629+00:00'
[2024-04-02T08:26:58.843+0000] {base.py:83} INFO - Using connection ID 'postgres_default' for task execution.
[2024-04-02T08:26:58.849+0000] {taskinstance.py:2731} ERROR - Task failed with exception
Traceback (most recent call last):
  File "/home/airflow/.local/lib/python3.8/site-packages/airflow/models/taskinstance.py", line 444, in _execute_task
    result = _execute_callable(context=context, **execute_callable_kwargs)
  File "/home/airflow/.local/lib/python3.8/site-packages/airflow/models/taskinstance.py", line 414, in _execute_callable
    return execute_callable(context=context, **execute_callable_kwargs)
  File "/home/airflow/.local/lib/python3.8/site-packages/airflow/operators/python.py", line 200, in execute
    return_value = self.execute_callable()
  File "/home/airflow/.local/lib/python3.8/site-packages/airflow/operators/python.py", line 217, in execute_callable
    return self.python_callable(*self.op_args, **self.op_kwargs)
  File "/opt/airflow/dags/airflow_dags.py", line 34, in ingest_data_to_postgres
    row['Name'], row['Address'], row['Transaction Amount'], row['Transaction Date'],
KeyError: 'Name'
[2024-04-02T08:26:58.867+0000] {taskinstance.py:1149} INFO - Marking task as FAILED. dag_id=data_ingestion_dag, task_id=ingest_data_to_postgres, execution_date=20240402T082149, start_date=20240402T082658, end_date=20240402T082658
[2024-04-02T08:26:58.889+0000] {standard_task_runner.py:107} ERROR - Failed to execute job 44 for task ingest_data_to_postgres ('Name'; 201)
[2024-04-02T08:26:58.928+0000] {local_task_job_runner.py:234} INFO - Task exited with return code 1
[2024-04-02T08:26:58.950+0000] {taskinstance.py:3312} INFO - 0 downstream tasks scheduled from follow-on schedule check
