[2024-04-02T08:09:40.540+0000] {taskinstance.py:1979} INFO - Dependencies all met for dep_context=non-requeueable deps ti=<TaskInstance: data_ingestion_dag.ingest_data_to_postgres manual__2024-04-02T08:04:30.641405+00:00 [queued]>
[2024-04-02T08:09:40.553+0000] {taskinstance.py:1979} INFO - Dependencies all met for dep_context=requeueable deps ti=<TaskInstance: data_ingestion_dag.ingest_data_to_postgres manual__2024-04-02T08:04:30.641405+00:00 [queued]>
[2024-04-02T08:09:40.554+0000] {taskinstance.py:2193} INFO - Starting attempt 2 of 2
[2024-04-02T08:09:40.576+0000] {taskinstance.py:2217} INFO - Executing <Task(PythonOperator): ingest_data_to_postgres> on 2024-04-02 08:04:30.641405+00:00
[2024-04-02T08:09:40.586+0000] {standard_task_runner.py:60} INFO - Started process 152 to run task
[2024-04-02T08:09:40.589+0000] {standard_task_runner.py:87} INFO - Running: ['***', 'tasks', 'run', 'data_ingestion_dag', 'ingest_data_to_postgres', 'manual__2024-04-02T08:04:30.641405+00:00', '--job-id', '40', '--raw', '--subdir', 'DAGS_FOLDER/***_dags.py', '--cfg-path', '/tmp/tmpsuw905mz']
[2024-04-02T08:09:40.592+0000] {standard_task_runner.py:88} INFO - Job 40: Subtask ingest_data_to_postgres
[2024-04-02T08:09:40.663+0000] {task_command.py:423} INFO - Running <TaskInstance: data_ingestion_dag.ingest_data_to_postgres manual__2024-04-02T08:04:30.641405+00:00 [running]> on host ba37e4cd94f0
[2024-04-02T08:09:40.775+0000] {taskinstance.py:2513} INFO - Exporting env vars: AIRFLOW_CTX_DAG_OWNER='***' AIRFLOW_CTX_DAG_ID='data_ingestion_dag' AIRFLOW_CTX_TASK_ID='ingest_data_to_postgres' AIRFLOW_CTX_EXECUTION_DATE='2024-04-02T08:04:30.641405+00:00' AIRFLOW_CTX_TRY_NUMBER='2' AIRFLOW_CTX_DAG_RUN_ID='manual__2024-04-02T08:04:30.641405+00:00'
[2024-04-02T08:09:40.846+0000] {taskinstance.py:2731} ERROR - Task failed with exception
Traceback (most recent call last):
  File "/home/airflow/.local/lib/python3.8/site-packages/airflow/models/taskinstance.py", line 444, in _execute_task
    result = _execute_callable(context=context, **execute_callable_kwargs)
  File "/home/airflow/.local/lib/python3.8/site-packages/airflow/models/taskinstance.py", line 414, in _execute_callable
    return execute_callable(context=context, **execute_callable_kwargs)
  File "/home/airflow/.local/lib/python3.8/site-packages/airflow/operators/python.py", line 200, in execute
    return_value = self.execute_callable()
  File "/home/airflow/.local/lib/python3.8/site-packages/airflow/operators/python.py", line 217, in execute_callable
    return self.python_callable(*self.op_args, **self.op_kwargs)
  File "/opt/airflow/dags/airflow_dags.py", line 28, in ingest_data_to_postgres
    connection = pg_hook.get_conn()
  File "/home/airflow/.local/lib/python3.8/site-packages/airflow/providers/postgres/hooks/postgres.py", line 131, in get_conn
    conn = deepcopy(self.connection or self.get_connection(conn_id))
  File "/home/airflow/.local/lib/python3.8/site-packages/airflow/hooks/base.py", line 82, in get_connection
    conn = Connection.get_connection_from_secrets(conn_id)
  File "/home/airflow/.local/lib/python3.8/site-packages/airflow/models/connection.py", line 514, in get_connection_from_secrets
    raise AirflowNotFoundException(f"The conn_id `{conn_id}` isn't defined")
airflow.exceptions.AirflowNotFoundException: The conn_id `postgres_default` isn't defined
[2024-04-02T08:09:40.857+0000] {taskinstance.py:1149} INFO - Marking task as FAILED. dag_id=data_ingestion_dag, task_id=ingest_data_to_postgres, execution_date=20240402T080430, start_date=20240402T080940, end_date=20240402T080940
[2024-04-02T08:09:40.880+0000] {standard_task_runner.py:107} ERROR - Failed to execute job 40 for task ingest_data_to_postgres (The conn_id `postgres_default` isn't defined; 152)
[2024-04-02T08:09:40.922+0000] {local_task_job_runner.py:234} INFO - Task exited with return code 1
[2024-04-02T08:09:40.951+0000] {taskinstance.py:3312} INFO - 0 downstream tasks scheduled from follow-on schedule check
