[2024-04-01T16:05:22.680+0000] {taskinstance.py:1979} INFO - Dependencies all met for dep_context=non-requeueable deps ti=<TaskInstance: data_ingestion_dag.ingest_data_to_postgres scheduled__2024-03-31T00:00:00+00:00 [queued]>
[2024-04-01T16:05:22.701+0000] {taskinstance.py:1979} INFO - Dependencies all met for dep_context=requeueable deps ti=<TaskInstance: data_ingestion_dag.ingest_data_to_postgres scheduled__2024-03-31T00:00:00+00:00 [queued]>
[2024-04-01T16:05:22.703+0000] {taskinstance.py:2193} INFO - Starting attempt 2 of 2
[2024-04-01T16:05:22.734+0000] {taskinstance.py:2217} INFO - Executing <Task(PythonOperator): ingest_data_to_postgres> on 2024-03-31 00:00:00+00:00
[2024-04-01T16:05:22.745+0000] {standard_task_runner.py:60} INFO - Started process 172 to run task
[2024-04-01T16:05:22.749+0000] {standard_task_runner.py:87} INFO - Running: ['***', 'tasks', 'run', 'data_ingestion_dag', 'ingest_data_to_postgres', 'scheduled__2024-03-31T00:00:00+00:00', '--job-id', '14', '--raw', '--subdir', 'DAGS_FOLDER/***_dags.py', '--cfg-path', '/tmp/tmps8e0ofo0']
[2024-04-01T16:05:22.753+0000] {standard_task_runner.py:88} INFO - Job 14: Subtask ingest_data_to_postgres
[2024-04-01T16:05:22.820+0000] {task_command.py:423} INFO - Running <TaskInstance: data_ingestion_dag.ingest_data_to_postgres scheduled__2024-03-31T00:00:00+00:00 [running]> on host 7ee3aa6f290b
[2024-04-01T16:05:22.935+0000] {taskinstance.py:2513} INFO - Exporting env vars: AIRFLOW_CTX_DAG_OWNER='***' AIRFLOW_CTX_DAG_ID='data_ingestion_dag' AIRFLOW_CTX_TASK_ID='ingest_data_to_postgres' AIRFLOW_CTX_EXECUTION_DATE='2024-03-31T00:00:00+00:00' AIRFLOW_CTX_TRY_NUMBER='2' AIRFLOW_CTX_DAG_RUN_ID='scheduled__2024-03-31T00:00:00+00:00'
[2024-04-01T16:05:22.937+0000] {taskinstance.py:2731} ERROR - Task failed with exception
Traceback (most recent call last):
  File "/home/airflow/.local/lib/python3.8/site-packages/airflow/models/taskinstance.py", line 444, in _execute_task
    result = _execute_callable(context=context, **execute_callable_kwargs)
  File "/home/airflow/.local/lib/python3.8/site-packages/airflow/models/taskinstance.py", line 414, in _execute_callable
    return execute_callable(context=context, **execute_callable_kwargs)
  File "/home/airflow/.local/lib/python3.8/site-packages/airflow/operators/python.py", line 200, in execute
    return_value = self.execute_callable()
  File "/home/airflow/.local/lib/python3.8/site-packages/airflow/operators/python.py", line 217, in execute_callable
    return self.python_callable(*self.op_args, **self.op_kwargs)
  File "/opt/airflow/dags/airflow_dags.py", line 15, in ingest_data_to_postgres
    with open('../../data_generation/kasapreko_data.csv', 'r') as csvfile:
FileNotFoundError: [Errno 2] No such file or directory: '../../data_generation/kasapreko_data.csv'
[2024-04-01T16:05:22.955+0000] {taskinstance.py:1149} INFO - Marking task as FAILED. dag_id=data_ingestion_dag, task_id=ingest_data_to_postgres, execution_date=20240331T000000, start_date=20240401T160522, end_date=20240401T160522
[2024-04-01T16:05:22.981+0000] {standard_task_runner.py:107} ERROR - Failed to execute job 14 for task ingest_data_to_postgres ([Errno 2] No such file or directory: '../../data_generation/kasapreko_data.csv'; 172)
[2024-04-01T16:05:23.002+0000] {local_task_job_runner.py:234} INFO - Task exited with return code 1
[2024-04-01T16:05:23.033+0000] {taskinstance.py:3312} INFO - 0 downstream tasks scheduled from follow-on schedule check
