[2024-04-01T20:48:31.281+0000] {taskinstance.py:1979} INFO - Dependencies all met for dep_context=non-requeueable deps ti=<TaskInstance: data_ingestion_dag.ingest_data_to_postgres manual__2024-04-01T20:48:23.695001+00:00 [queued]>
[2024-04-01T20:48:31.294+0000] {taskinstance.py:1979} INFO - Dependencies all met for dep_context=requeueable deps ti=<TaskInstance: data_ingestion_dag.ingest_data_to_postgres manual__2024-04-01T20:48:23.695001+00:00 [queued]>
[2024-04-01T20:48:31.294+0000] {taskinstance.py:2193} INFO - Starting attempt 1 of 2
[2024-04-01T20:48:31.317+0000] {taskinstance.py:2217} INFO - Executing <Task(PythonOperator): ingest_data_to_postgres> on 2024-04-01 20:48:23.695001+00:00
[2024-04-01T20:48:31.327+0000] {standard_task_runner.py:60} INFO - Started process 630 to run task
[2024-04-01T20:48:31.336+0000] {standard_task_runner.py:87} INFO - Running: ['***', 'tasks', 'run', 'data_ingestion_dag', 'ingest_data_to_postgres', 'manual__2024-04-01T20:48:23.695001+00:00', '--job-id', '27', '--raw', '--subdir', 'DAGS_FOLDER/***_dags.py', '--cfg-path', '/tmp/tmpvlpgzy1i']
[2024-04-01T20:48:31.339+0000] {standard_task_runner.py:88} INFO - Job 27: Subtask ingest_data_to_postgres
[2024-04-01T20:48:31.410+0000] {task_command.py:423} INFO - Running <TaskInstance: data_ingestion_dag.ingest_data_to_postgres manual__2024-04-01T20:48:23.695001+00:00 [running]> on host 711088c69ec0
[2024-04-01T20:48:31.515+0000] {taskinstance.py:2513} INFO - Exporting env vars: AIRFLOW_CTX_DAG_OWNER='***' AIRFLOW_CTX_DAG_ID='data_ingestion_dag' AIRFLOW_CTX_TASK_ID='ingest_data_to_postgres' AIRFLOW_CTX_EXECUTION_DATE='2024-04-01T20:48:23.695001+00:00' AIRFLOW_CTX_TRY_NUMBER='1' AIRFLOW_CTX_DAG_RUN_ID='manual__2024-04-01T20:48:23.695001+00:00'
[2024-04-01T20:48:31.518+0000] {taskinstance.py:2731} ERROR - Task failed with exception
Traceback (most recent call last):
  File "/home/airflow/.local/lib/python3.8/site-packages/airflow/models/taskinstance.py", line 444, in _execute_task
    result = _execute_callable(context=context, **execute_callable_kwargs)
  File "/home/airflow/.local/lib/python3.8/site-packages/airflow/models/taskinstance.py", line 414, in _execute_callable
    return execute_callable(context=context, **execute_callable_kwargs)
  File "/home/airflow/.local/lib/python3.8/site-packages/airflow/operators/python.py", line 200, in execute
    return_value = self.execute_callable()
  File "/home/airflow/.local/lib/python3.8/site-packages/airflow/operators/python.py", line 217, in execute_callable
    return self.python_callable(*self.op_args, **self.op_kwargs)
  File "/opt/airflow/dags/airflow_dags.py", line 15, in ingest_data_to_postgres
    with open('./data_generation/kasapreko_data.csv', 'r') as csvfile:
FileNotFoundError: [Errno 2] No such file or directory: './data_generation/kasapreko_data.csv'
[2024-04-01T20:48:31.531+0000] {taskinstance.py:1149} INFO - Marking task as UP_FOR_RETRY. dag_id=data_ingestion_dag, task_id=ingest_data_to_postgres, execution_date=20240401T204823, start_date=20240401T204831, end_date=20240401T204831
[2024-04-01T20:48:31.551+0000] {standard_task_runner.py:107} ERROR - Failed to execute job 27 for task ingest_data_to_postgres ([Errno 2] No such file or directory: './data_generation/kasapreko_data.csv'; 630)
[2024-04-01T20:48:31.584+0000] {local_task_job_runner.py:234} INFO - Task exited with return code 1
[2024-04-01T20:48:31.608+0000] {taskinstance.py:3312} INFO - 0 downstream tasks scheduled from follow-on schedule check
